Workbook
Name AcServices: Services!$A$1:$B$117

Sheet Sheet1
B1: Node1Id | D1: Node2Id | F1: Node3Id
A2: School Admissions | B2: =VLOOKUP(A2,Services!$B$2:$C$118,2,0) -> 6c5e7af8-dd22-46d6-87b1-4436f2e4ab2f | C2: Assessments Coaching | D2: =VLOOKUP(C2,Services!$B$2:$C$118,2,0) -> 672d3944-dd97-4a70-be11-fbc720d98645 | F2: =VLOOKUP(E2,Services!$B$2:$C$118,2,0) -> #N/A
A3: School Admissions | B3: =VLOOKUP(A3,Services!$B$2:$C$118,2,0) -> 6c5e7af8-dd22-46d6-87b1-4436f2e4ab2f | C3: Interview Coaching | D3: =VLOOKUP(C3,Services!$B$2:$C$118,2,0) -> 2c3d46f8-ca19-4631-a47f-e808c4341a52 | F3: =VLOOKUP(E3,Services!$B$2:$C$118,2,0) -> #N/A
A4: School Admissions | B4: =VLOOKUP(A4,Services!$B$2:$C$118,2,0) -> 6c5e7af8-dd22-46d6-87b1-4436f2e4ab2f | C4: Assessments Coaching | D4: =VLOOKUP(C4,Services!$B$2:$C$118,2,0) -> 672d3944-dd97-4a70-be11-fbc720d98645 | E4: Entry Level | F4: =VLOOKUP(E4,Services!$B$2:$C$118,2,0) -> eceb9a9b-0ea9-4bf9-8b62-68e947ac2682
A5: School Admissions | B5: =VLOOKUP(A5,Services!$B$2:$C$118,2,0) -> 6c5e7af8-dd22-46d6-87b1-4436f2e4ab2f | C5: Interview Coaching | D5: =VLOOKUP(C5,Services!$B$2:$C$118,2,0) -> 2c3d46f8-ca19-4631-a47f-e808c4341a52 | E5: Entry Level | F5: =VLOOKUP(E5,Services!$B$2:$C$118,2,0) -> eceb9a9b-0ea9-4bf9-8b62-68e947ac2682
A6: School Admissions | B6: =VLOOKUP(A6,Services!$B$2:$C$118,2,0) -> 6c5e7af8-dd22-46d6-87b1-4436f2e4ab2f | C6: Assessments Coaching | D6: =VLOOKUP(C6,Services!$B$2:$C$118,2,0) -> 672d3944-dd97-4a70-be11-fbc720d98645 | E6: GCSE | F6: =VLOOKUP(E6,Services!$B$2:$C$118,2,0) -> 6aa0d3b8-6229-4945-809a-a704f39b1b22
A7: School Admissions | B7: =VLOOKUP(A7,Services!$B$2:$C$118,2,0) -> 6c5e7af8-dd22-46d6-87b1-4436f2e4ab2f | C7: Interview Coaching | D7: =VLOOKUP(C7,Services!$B$2:$C$118,2,0) -> 2c3d46f8-ca19-4631-a47f-e808c4341a52 | E7: GCSE | F7: =VLOOKUP(E7,Services!$B$2:$C$118,2,0) -> 6aa0d3b8-6229-4945-809a-a704f39b1b22
A8: School Admissions | B8: =VLOOKUP(A8,Services!$B$2:$C$118,2,0) -> 6c5e7af8-dd22-46d6-87b1-4436f2e4ab2f | C8: Assessments Coaching | D8: =VLOOKUP(C8,Services!$B$2:$C$118,2,0) -> 672d3944-dd97-4a70-be11-fbc720d98645 | E8: A Level | F8: =VLOOKUP(E8,Services!$B$2:$C$118,2,0) -> 9a8d9777-ead3-4344-af27-d9a595f5de5c
A9: School Admissions | B9: =VLOOKUP(A9,Services!$B$2:$C$118,2,0) -> 6c5e7af8-dd22-46d6-87b1-4436f2e4ab2f | C9: Interview Coaching | D9: =VLOOKUP(C9,Services!$B$2:$C$118,2,0) -> 2c3d46f8-ca19-4631-a47f-e808c4341a52 | E9: A Level | F9: =VLOOKUP(E9,Services!$B$2:$C$118,2,0) -> 9a8d9777-ead3-4344-af27-d9a595f5de5c
A10: University Admissions | B10: =VLOOKUP(A10,Services!$B$2:$C$118,2,0) -> b4d0ce54-6fdc-4f8f-9265-7b56896bc2b1 | C10: CV Building | D10: =VLOOKUP(C10,Services!$B$2:$C$118,2,0) -> bcf7d458-6d6b-4c22-ae23-221acb81f24f | F10: =VLOOKUP(E10,Services!$B$2:$C$118,2,0) -> #N/A
A11: University Admissions | B11: =VLOOKUP(A11,Services!$B$2:$C$118,2,0) -> b4d0ce54-6fdc-4f8f-9265-7b56896bc2b1 | C11: Personal Statement Coaching | D11: =VLOOKUP(C11,Services!$B$2:$C$118,2,0) -> 1b7f6831-37f9-44e5-9fa9-8ee421061701 | F11: =VLOOKUP(E11,Services!$B$2:$C$118,2,0) -> #N/A
A12: University Admissions | B12: =VLOOKUP(A12,Services!$B$2:$C$118,2,0) -> b4d0ce54-6fdc-4f8f-9265-7b56896bc2b1 | C12: Art & Design Portfolio Coaching | D12: =VLOOKUP(C12,Services!$B$2:$C$118,2,0) -> be67df63-0749-4a39-9467-d2a0336db4b4 | F12: =VLOOKUP(E12,Services!$B$2:$C$118,2,0) -> #N/A
A13: University Admissions | B13: =VLOOKUP(A13,Services!$B$2:$C$118,2,0) -> b4d0ce54-6fdc-4f8f-9265-7b56896bc2b1 | C13: Reference Letter Translation | D13: =VLOOKUP(C13,Services!$B$2:$C$118,2,0) -> 8e9128d9-109d-4c8a-a758-ec6564d5ddbd | F13: =VLOOKUP(E13,Services!$B$2:$C$118,2,0) -> #N/A
A14: University Admissions | B14: =VLOOKUP(A14,Services!$B$2:$C$118,2,0) -> b4d0ce54-6fdc-4f8f-9265-7b56896bc2b1 | C14: Sample Writing Coaching | D14: =VLOOKUP(C14,Services!$B$2:$C$118,2,0) -> 9b62d92f-09ce-46b5-b09e-69136e867525 | F14: =VLOOKUP(E14,Services!$B$2:$C$118,2,0) -> #N/A
A15: University Admissions | B15: =VLOOKUP(A15,Services!$B$2:$C$118,2,0) -> b4d0ce54-6fdc-4f8f-9265-7b56896bc2b1 | C15: Admissions Test Coaching | D15: =VLOOKUP(C15,Services!$B$2:$C$118,2,0) -> 3382a73a-885b-4191-a390-6f558c8912db | F15: =VLOOKUP(E15,Services!$B$2:$C$118,2,0) -> #N/A
A16: University Admissions | B16: =VLOOKUP(A16,Services!$B$2:$C$118,2,0) -> b4d0ce54-6fdc-4f8f-9265-7b56896bc2b1 | C16: Interview Coaching | D16: =VLOOKUP(C16,Services!$B$2:$C$118,2,0) -> 2c3d46f8-ca19-4631-a47f-e808c4341a52 | F16: =VLOOKUP(E16,Services!$B$2:$C$118,2,0) -> #N/A
A17: University Admissions | B17: =VLOOKUP(A17,Services!$B$2:$C$118,2,0) -> b4d0ce54-6fdc-4f8f-9265-7b56896bc2b1 | C17: CV Building | D17: =VLOOKUP(C17,Services!$B$2:$C$118,2,0) -> bcf7d458-6d6b-4c22-ae23-221acb81f24f | E17: Undergrad | F17: =VLOOKUP(E17,Services!$B$2:$C$118,2,0) -> e57b609a-ff04-4671-9076-23c69f6198bb
A18: University Admissions | B18: =VLOOKUP(A18,Services!$B$2:$C$118,2,0) -> b4d0ce54-6fdc-4f8f-9265-7b56896bc2b1 | C18: Personal Statement Coaching | D18: =VLOOKUP(C18,Services!$B$2:$C$118,2,0) -> 1b7f6831-37f9-44e5-9fa9-8ee421061701 | E18: Undergrad | F18: =VLOOKUP(E18,Services!$B$2:$C$118,2,0) -> e57b609a-ff04-4671-9076-23c69f6198bb
A19: University Admissions | B19: =VLOOKUP(A19,Services!$B$2:$C$118,2,0) -> b4d0ce54-6fdc-4f8f-9265-7b56896bc2b1 | C19: Art & Design Portfolio Coaching | D19: =VLOOKUP(C19,Services!$B$2:$C$118,2,0) -> be67df63-0749-4a39-9467-d2a0336db4b4 | E19: Undergrad | F19: =VLOOKUP(E19,Services!$B$2:$C$118,2,0) -> e57b609a-ff04-4671-9076-23c69f6198bb
A20: University Admissions | B20: =VLOOKUP(A20,Services!$B$2:$C$118,2,0) -> b4d0ce54-6fdc-4f8f-9265-7b56896bc2b1 | C20: Reference Letter Translation | D20: =VLOOKUP(C20,Services!$B$2:$C$118,2,0) -> 8e9128d9-109d-4c8a-a758-ec6564d5ddbd | E20: Undergrad | F20: =VLOOKUP(E20,Services!$B$2:$C$118,2,0) -> e57b609a-ff04-4671-9076-23c69f6198bb
A21: University Admissions | B21: =VLOOKUP(A21,Services!$B$2:$C$118,2,0) -> b4d0ce54-6fdc-4f8f-9265-7b56896bc2b1 | C21: Sample Writing Coaching | D21: =VLOOKUP(C21,Services!$B$2:$C$118,2,0) -> 9b62d92f-09ce-46b5-b09e-69136e867525 | E21: Undergrad | F21: =VLOOKUP(E21,Services!$B$2:$C$118,2,0) -> e57b609a-ff04-4671-9076-23c69f6198bb
A22: University Admissions | B22: =VLOOKUP(A22,Services!$B$2:$C$118,2,0) -> b4d0ce54-6fdc-4f8f-9265-7b56896bc2b1 | C22: Admissions Test Coaching | D22: =VLOOKUP(C22,Services!$B$2:$C$118,2,0) -> 3382a73a-885b-4191-a390-6f558c8912db | E22: Undergrad | F22: =VLOOKUP(E22,Services!$B$2:$C$118,2,0) -> e57b609a-ff04-4671-9076-23c69f6198bb
A23: University Admissions | B23: =VLOOKUP(A23,Services!$B$2:$C$118,2,0) -> b4d0ce54-6fdc-4f8f-9265-7b56896bc2b1 | C23: Interview Coaching | D23: =VLOOKUP(C23,Services!$B$2:$C$118,2,0) -> 2c3d46f8-ca19-4631-a47f-e808c4341a52 | E23: Undergrad | F23: =VLOOKUP(E23,Services!$B$2:$C$118,2,0) -> e57b609a-ff04-4671-9076-23c69f6198bb
A24: University Admissions | B24: =VLOOKUP(A24,Services!$B$2:$C$118,2,0) -> b4d0ce54-6fdc-4f8f-9265-7b56896bc2b1 | C24: CV Building | D24: =VLOOKUP(C24,Services!$B$2:$C$118,2,0) -> bcf7d458-6d6b-4c22-ae23-221acb81f24f | E24: Masters | F24: =VLOOKUP(E24,Services!$B$2:$C$118,2,0) -> 91178014-aa7f-4b2c-a000-f38fcc56b0cb
A25: University Admissions | B25: =VLOOKUP(A25,Services!$B$2:$C$118,2,0) -> b4d0ce54-6fdc-4f8f-9265-7b56896bc2b1 | C25: Personal Statement Coaching | D25: =VLOOKUP(C25,Services!$B$2:$C$118,2,0) -> 1b7f6831-37f9-44e5-9fa9-8ee421061701 | E25: Masters | F25: =VLOOKUP(E25,Services!$B$2:$C$118,2,0) -> 91178014-aa7f-4b2c-a000-f38fcc56b0cb
A26: University Admissions | B26: =VLOOKUP(A26,Services!$B$2:$C$118,2,0) -> b4d0ce54-6fdc-4f8f-9265-7b56896bc2b1 | C26: Art & Design Portfolio Coaching | D26: =VLOOKUP(C26,Services!$B$2:$C$118,2,0) -> be67df63-0749-4a39-9467-d2a0336db4b4 | E26: Masters | F26: =VLOOKUP(E26,Services!$B$2:$C$118,2,0) -> 91178014-aa7f-4b2c-a000-f38fcc56b0cb
A27: University Admissions | B27: =VLOOKUP(A27,Services!$B$2:$C$118,2,0) -> b4d0ce54-6fdc-4f8f-9265-7b56896bc2b1 | C27: Reference Letter Translation | D27: =VLOOKUP(C27,Services!$B$2:$C$118,2,0) -> 8e9128d9-109d-4c8a-a758-ec6564d5ddbd | E27: Masters | F27: =VLOOKUP(E27,Services!$B$2:$C$118,2,0) -> 91178014-aa7f-4b2c-a000-f38fcc56b0cb
A28: University Admissions | B28: =VLOOKUP(A28,Services!$B$2:$C$118,2,0) -> b4d0ce54-6fdc-4f8f-9265-7b56896bc2b1 | C28: Sample Writing Coaching | D28: =VLOOKUP(C28,Services!$B$2:$C$118,2,0) -> 9b62d92f-09ce-46b5-b09e-69136e867525 | E28: Masters | F28: =VLOOKUP(E28,Services!$B$2:$C$118,2,0) -> 91178014-aa7f-4b2c-a000-f38fcc56b0cb
... A37: University Admissions | B37: =VLOOKUP(A37,Services!$B$2:$C$118,2,0) -> b4d0ce54-6fdc-4f8f-9265-7b56896bc2b1 | C37: Interview Coaching | D37: =VLOOKUP(C37,Services!$B$2:$C$118,2,0) -> 2c3d46f8-ca19-4631-a47f-e808c4341a52 | E37: Doctorate | F37: =VLOOKUP(E37,Services!$B$2:$C$118,2,0) -> 4d817b44-324c-4cf8-871a-ae0d61ede07b
A38: Academic Support | B38: =VLOOKUP(A38,Services!$B$2:$C$118,2,0) -> 5065a4c4-9e2d-465b-b8a2-e3f1d89bfcc7 | C38: Academic Tutoring | D38: =VLOOKUP(C38,Services!$B$2:$C$118,2,0) -> d20282ba-fbd3-4e72-81c0-3ec16309309c | F38: =VLOOKUP(E38,Services!$B$2:$C$118,2,0) -> #N/A
A39: Academic Support | B39: =VLOOKUP(A39,Services!$B$2:$C$118,2,0) -> 5065a4c4-9e2d-465b-b8a2-e3f1d89bfcc7 | C39: Assignment Feedback | D39: =VLOOKUP(C39,Services!$B$2:$C$118,2,0) -> 90105083-583c-49b7-937e-22ce838591c0 | F39: =VLOOKUP(E39,Services!$B$2:$C$118,2,0) -> #N/A
A40: Academic Support | B40: =VLOOKUP(A40,Services!$B$2:$C$118,2,0) -> 5065a4c4-9e2d-465b-b8a2-e3f1d89bfcc7 | C40: Proofreading & Copy Editing | D40: =VLOOKUP(C40,Services!$B$2:$C$118,2,0) -> b0cd2298-822a-4515-9b61-4b4ee763bd98 | F40: =VLOOKUP(E40,Services!$B$2:$C$118,2,0) -> #N/A
A41: Academic Support | B41: =VLOOKUP(A41,Services!$B$2:$C$118,2,0) -> 5065a4c4-9e2d-465b-b8a2-e3f1d89bfcc7 | C41: Research Solutions | D41: =VLOOKUP(C41,Services!$B$2:$C$118,2,0) -> 263C4D7D-6AC7-4F4A-8B61-E6B3D72D9C5C | F41: =VLOOKUP(E41,Services!$B$2:$C$118,2,0) -> #N/A
A42: Academic Support | B42: =VLOOKUP(A42,Services!$B$2:$C$118,2,0) -> 5065a4c4-9e2d-465b-b8a2-e3f1d89bfcc7 | C42: Academic Tutoring | D42: =VLOOKUP(C42,Services!$B$2:$C$118,2,0) -> d20282ba-fbd3-4e72-81c0-3ec16309309c | E42: GCSE | F42: =VLOOKUP(E42,Services!$B$2:$C$118,2,0) -> 6aa0d3b8-6229-4945-809a-a704f39b1b22
A43: Academic Support | B43: =VLOOKUP(A43,Services!$B$2:$C$118,2,0) -> 5065a4c4-9e2d-465b-b8a2-e3f1d89bfcc7 | C43: Assignment Feedback | D43: =VLOOKUP(C43,Services!$B$2:$C$118,2,0) -> 90105083-583c-49b7-937e-22ce838591c0 | E43: GCSE | F43: =VLOOKUP(E43,Services!$B$2:$C$118,2,0) -> 6aa0d3b8-6229-4945-809a-a704f39b1b22
A44: Academic Support | B44: =VLOOKUP(A44,Services!$B$2:$C$118,2,0) -> 5065a4c4-9e2d-465b-b8a2-e3f1d89bfcc7 | C44: Academic Tutoring | D44: =VLOOKUP(C44,Services!$B$2:$C$118,2,0) -> d20282ba-fbd3-4e72-81c0-3ec16309309c | E44: A Level | F44: =VLOOKUP(E44,Services!$B$2:$C$118,2,0) -> 9a8d9777-ead3-4344-af27-d9a595f5de5c
A45: Academic Support | B45: =VLOOKUP(A45,Services!$B$2:$C$118,2,0) -> 5065a4c4-9e2d-465b-b8a2-e3f1d89bfcc7 | C45: Assignment Feedback | D45: =VLOOKUP(C45,Services!$B$2:$C$118,2,0) -> 90105083-583c-49b7-937e-22ce838591c0 | E45: A Level | F45: =VLOOKUP(E45,Services!$B$2:$C$118,2,0) -> 9a8d9777-ead3-4344-af27-d9a595f5de5c
A46: Academic Support | B46: =VLOOKUP(A46,Services!$B$2:$C$118,2,0) -> 5065a4c4-9e2d-465b-b8a2-e3f1d89bfcc7 | C46: Academic Tutoring | D46: =VLOOKUP(C46,Services!$B$2:$C$118,2,0) -> d20282ba-fbd3-4e72-81c0-3ec16309309c | E46: Undergrad, Masters, Doctorate | F46: =VLOOKUP(E46,Services!$B$2:$C$118,2,0) -> 359a60af-d41c-4aa2-8ce3-f1f3cee35c24
A47: Academic Support | B47: =VLOOKUP(A47,Services!$B$2:$C$118,2,0) -> 5065a4c4-9e2d-465b-b8a2-e3f1d89bfcc7 | C47: Assignment Feedback | D47: =VLOOKUP(C47,Services!$B$2:$C$118,2,0) -> 90105083-583c-49b7-937e-22ce838591c0 | E47: Undergrad, Masters, Doctorate | F47: =VLOOKUP(E47,Services!$B$2:$C$118,2,0) -> 359a60af-d41c-4aa2-8ce3-f1f3cee35c24
A48: Academic Support | B48: =VLOOKUP(A48,Services!$B$2:$C$118,2,0) -> 5065a4c4-9e2d-465b-b8a2-e3f1d89bfcc7 | C48: Proofreading & Copy Editing | D48: =VLOOKUP(C48,Services!$B$2:$C$118,2,0) -> b0cd2298-822a-4515-9b61-4b4ee763bd98 | E48: Undergrad, Masters, Doctorate | F48: =VLOOKUP(E48,Services!$B$2:$C$118,2,0) -> 359a60af-d41c-4aa2-8ce3-f1f3cee35c24
...

Sheet Services
A1: Id | B1: Name | C1: Id
A2: 6c5e7af8-dd22-46d6-87b1-4436f2e4ab2f | B2: School Admissions | C2: 6c5e7af8-dd22-46d6-87b1-4436f2e4ab2f
A3: b4d0ce54-6fdc-4f8f-9265-7b56896bc2b1 | B3: University Admissions | C3: b4d0ce54-6fdc-4f8f-9265-7b56896bc2b1
A4: 5065a4c4-9e2d-465b-b8a2-e3f1d89bfcc7 | B4: Academic Support | C4: 5065a4c4-9e2d-465b-b8a2-e3f1d89bfcc7
A5: 2261bfdb-0998-4644-aeae-6af562d3373d | B5: Study Skills | C5: 2261bfdb-0998-4644-aeae-6af562d3373d
A6: 24f25767-bc02-46e1-8587-325dd8c3f6a4 | B6: Career Consultancy | C6: 24f25767-bc02-46e1-8587-325dd8c3f6a4
A7: 3ed54d43-46fa-43ce-8994-d10fff8604a6 | B7: Language Tutoring | C7: 3ed54d43-46fa-43ce-8994-d10fff8604a6
A8: fac851ab-bb32-4161-adce-38062ddd3c59 | B8: Interpretering | C8: fac851ab-bb32-4161-adce-38062ddd3c59
A9: bf893a87-f835-4c4e-802c-3488343962dd | B9: Guardianship | C9: bf893a87-f835-4c4e-802c-3488343962dd
A10: 8327fd9d-47be-4b79-817c-8364e60cc2b7 | B10: Visa Application Consultancy | C10: 8327fd9d-47be-4b79-817c-8364e60cc2b7
A11: 709a78df-a2b0-43c1-b7f3-3a354cfe8e7f | B11: Academic English Coaching | C11: 709a78df-a2b0-43c1-b7f3-3a354cfe8e7f
A12: 76410084-1858-475b-a96c-87b4602daebc | B12: English Language Test for Professionals Coaching | C12: 76410084-1858-475b-a96c-87b4602daebc
... A91: 263C4D7D-6AC7-4F4A-8B61-E6B3D72D9C5C | B91: Research Solutions | C91: 263C4D7D-6AC7-4F4A-8B61-E6B3D72D9C5C
